<mujoco>
	<option timestep="0.0001" integrator="RK4">
		<flag sensornoise="enable" energy="enable" contact="disable"/>
	</option>
	<worldbody>
        <light diffuse=".5 .5 .5" pos="0 0 3" dir="0 0 -1"/>
		<geom type="plane" size="1 1 0.1" rgba=".9 0 0 1"/>
		<body pos="0 0 2.5" euler="0 180 0">
			<joint name="HFE" type="hinge" axis="0 -1 0" pos="0 0 0.5"/>
			<geom type="cylinder" size=".05 .5" rgba="0 .9 0 1" mass="1"/>
		
			<!-- <body pos="0 0.1 -1" euler="0 0 0">
				<joint name="KFE" type="hinge" axis="0 -1 0" pos="0 0 0.5"/>
				<geom type="cylinder" size=".05 .5" rgba="0 0 0.9 1" mass="1"/>
				
			</body> -->
		</body>
	</worldbody>
	
	<actuator>
		<motor joint="HFE" name="torque1" gear="1" ctrllimited="true" ctrlrange="-100 100" />
		<!-- <position name="pos_servo1" joint="HFE" kp="100" /> -->
		<!-- <velocity name="vel_servo1" joint="HFE" kv="10" /> -->

	</actuator>
	
	
</mujoco>


<!-- <actuator>
		<motor joint="KFE" name="torque2" gear="1" ctrllimited="true" ctrlrange="-100 100" />
		<!-- <position name="pos_servo2" joint="KFE" kp="100" />
		<velocity name="vel_servo2" joint="KFE" kv="10" /> -->
	</actuator> -->
